<?xml version="1.0" ?>
<robot name="blank_panther" xmlns:xacro="http://ros.org/wiki/xacro">

    <link name="body">
        <visual>
            <geometry>
                <!--mesh filename="meshes/bp_body.obj"/-->
                <mesh filename="meshes/bp_body2.dae"/>
            </geometry>
            <origin rpy="0.0 0.0 0.0" xyz="0.0 0.0 0.0"/>
        </visual>
        <inertial>
            <mass value="3.72"/>
            <!-- <mass value="8.3"/> -->
            <origin xyz="0.0 0.0 -0.003"/>
            <inertia ixx="0.016269" ixy="0" ixz="0" iyy="0.050813" iyz="0" izz="0.060989"/>
        </inertial>
        <collision>
            <origin rpy="0 0 0" xyz="0 0 0"/>
            <geometry>
                <box size="0.3 0.2 0.1"/>
            </geometry>
        </collision>
    </link>

    <link name="dummy_mass">
        <inertial>
            <!--mass value="2.955"/-->
            <mass value="0"/>
            <!-- <mass value="8.3"/> -->
            <origin xyz="0.0 0.0 -0.003"/>
            <!--inertia ixx="0.013355" ixy="0" ixz="0" iyy="0.040234" iyz="0" izz="0.048945"/-->
            <inertia ixx="0.0" ixy="0" ixz="0" iyy="0.0" iyz="0" izz="0.0"/>
        </inertial>
    </link>

    <joint name="mass2body" type="fixed">
        <origin xyz="0 0 0" rpy="0 0 0"/>
        <parent link="body"/>
        <child link="dummy_mass"/>
    </joint>

    <!--!!!!!!!!!!!!!!!!!!!! Front Right Leg !!!!!!!!!!!!!!!!!!!!-->

    <joint name="torso_to_abduct_fr_j" type="continuous">
        <axis xyz="1 0 0"/>
        <origin rpy="0 0 0" xyz="0.212 -0.051 0.0"/>
        <parent link="body"/>
        <child link="abduct_fr"/>
        <limit effort="18" lower="-6.28" upper="6.28" velocity="25"/>
        <dynamics damping="0.01" friction="0.2"/>
    </joint>

    <link name="abduct_fr">
        <inertial>
            <mass value="0.54"/>
            <origin xyz="0.058 -0.00485 0."/>
            <inertia ixx="0.000391" ixy="0.000000" ixz="0.000000"
                     iyy="0.000739" iyz="0.000000" izz="0.000488"/>
        </inertial>
        <visual>
            <geometry>
                <!--mesh filename="meshes/bp_abad_fr.obj"/-->
                <mesh filename="meshes/bp_abad2.dae"/>
            </geometry>
            <origin rpy="3.1415926 0 0" xyz="-0.063 0.0 0.0"/>
        </visual>
    </link>

    <joint name="abduct_fr_to_thigh_fr_j" type="continuous">
        <axis xyz="0 -1 0"/>
        <origin rpy="0.0 0.0 0.0" xyz="0.0 -0.085 0.00"/>
        <parent link="abduct_fr"/>
        <child link="thigh_fr"/>
        <limit effort="18" lower="-6.28" upper="6.28" velocity="25"/>
        <dynamics damping="0.01" friction="0.2"/>
    </joint>

    <link name="thigh_fr">
        <inertial>
            <mass value="0.636"/>
            <origin xyz="0.0 0.019 -0.01865"/>
            <inertia ixx="0.001724" ixy="0.0" ixz="0.0"
                     iyy="0.001907" iyz="0.000228" izz="0.000468"/>
        </inertial>
        <visual>
            <geometry>
                <!--mesh filename="meshes/bp_upper_fr.obj"/-->
                <mesh filename="meshes/bp_upper_r.dae"/>
            </geometry>
            <origin rpy="0.0 0.0 0.0" xyz="0.0 0.0 0.0"/>
        </visual>
    </link>

    <joint name="thigh_fr_to_knee_fr_j" type="continuous">
        <axis xyz="0 -1 0"/>
        <origin rpy="0.0 0 0.0" xyz="0.0 0.0 -0.201"/>
        <parent link="thigh_fr"/>
        <child link="shank_fr"/>
        <limit effort="27" lower="-6.28" upper="6.28" velocity="17"/>
        <dynamics damping="0.01" friction="0.2"/>
    </joint>

    <link name="shank_fr">
        <inertial>
            <mass value="0.064"/>
            <origin xyz="0.0 0.0 -0.0865"/>
            <inertia ixx="0.000716" ixy="0" ixz="0.0" iyy="0.000721" iyz="0" izz="0.000012"/>
        </inertial>
        <visual>
            <geometry>
                <!--mesh filename="meshes/bp_lower.obj"/-->
                <mesh filename="meshes/bp_lower.dae"/>
            </geometry>
            <origin rpy="0.0 0 0.0" xyz="0.0 0.0 0.0"/>
        </visual>
    </link>

    <link name="toe_fr">
        <contact>
            <friction_anchor/>
            <stiffness value="30000.0"/>
            <damping value="1000.0"/>
            <spinning_friction value="0.3"/>
            <lateral_friction value="3.0"/>
        </contact>
<!--        <visual>-->
<!--            <origin rpy="0 0 0" xyz="0 0 0"/>-->
<!--            <geometry>-->
<!--                <sphere radius="0.0275"/>-->
<!--            </geometry>-->
<!--            <material name="darkgray"/>-->
<!--        </visual>-->
        <collision>
            <origin rpy="0 0 0" xyz="0 0 0"/>
            <geometry>
                <sphere radius="0.0275"/>
            </geometry>
        </collision>
        <inertial>
            <mass value="0.05"/>
            <!--            <mass value="0.005"/>-->
            <inertia ixx="0.000025" ixy="0" ixz="0" iyy="0.000025" iyz="0" izz="0.000025"/>
        </inertial>
    </link>

    <joint name="toe_fr_joint" type="fixed">
        <parent link="shank_fr"/>
        <child link="toe_fr"/>
        <origin xyz="0 0 -0.19"/>
        <dynamics damping="0.0" friction="0.0"/>
    </joint>

    <!--!!!!!!!!!!!!!!!!!!!! Front Left Leg !!!!!!!!!!!!!!!!!!!!-->

    <joint name="torso_to_abduct_fl_j" type="continuous">
        <axis xyz="1 0 0"/>
        <origin rpy="0 0 0" xyz="0.212 0.051 0.0"/>
        <parent link="body"/>
        <child link="abduct_fl"/>
        <limit effort="18" lower="-6.28" upper="6.28" velocity="25"/>
        <dynamics damping="0.01" friction="0.2"/>
    </joint>

    <link name="abduct_fl">
        <inertial>
            <mass value="0.54"/>
            <origin xyz="0.058 0.00485 0."/>
            <inertia ixx="0.000391" ixy="0.000000" ixz="0.000000"
                     iyy="0.000739" iyz="0.000000" izz="0.000488"/>
        </inertial>
        <visual>
            <geometry>
                <!--mesh filename="meshes/bp_abad_fl.obj"/-->
                <mesh filename="meshes/bp_abad2.dae"/>
            </geometry>
            <origin rpy="0 0 0" xyz="-0.063 0.0 0.0"/>
        </visual>
    </link>

    <joint name="abduct_fl_to_thigh_fl_j" type="continuous">
        <axis xyz="0 -1 0"/>
        <origin rpy="0.0 0.0 0.0" xyz="0.0 0.085 0.00"/>
        <parent link="abduct_fl"/>
        <child link="thigh_fl"/>
        <limit effort="18" lower="-6.28" upper="6.28" velocity="25"/>
        <dynamics damping="0.01" friction="0.2"/>
    </joint>

    <link name="thigh_fl">
        <inertial>
            <mass value="0.636"/>
            <origin xyz="0.0 -0.019 -0.01865"/>
            <inertia ixx="0.001724" ixy="0.0" ixz="0.0"
                     iyy="0.001907" iyz="-0.000228" izz="0.000468"/>
        </inertial>
        <visual>
            <geometry>
                <!--mesh filename="meshes/bp_upper_fl.obj"/-->
                <mesh filename="meshes/bp_upper_l.dae"/>
            </geometry>
            <origin rpy="0.0 0.0 0.0" xyz="0.0 0.0 0.0"/>
        </visual>
    </link>

    <joint name="thigh_fl_to_knee_fl_j" type="continuous">
        <axis xyz="0 -1 0"/>
        <origin rpy="0.0 0 0.0" xyz="0.0 0.0 -0.201"/>
        <parent link="thigh_fl"/>
        <child link="shank_fl"/>
        <limit effort="27" lower="-6.28" upper="6.28" velocity="17"/>
        <dynamics damping="0.01" friction="0.2"/>
    </joint>

    <link name="shank_fl">
        <inertial>
            <mass value="0.064"/>
            <origin xyz="0.0 0.0 -0.0865"/>
            <inertia ixx="0.000716" ixy="0" ixz="0.0" iyy="0.000721" iyz="0" izz="0.000012"/>
        </inertial>
        <visual>
            <geometry>
                <!--                <mesh filename="meshes/bp_lower.obj"/>-->
                <mesh filename="meshes/bp_lower.dae"/>
            </geometry>
            <origin rpy="0.0 0 0.0" xyz="0.0 0.0 0.0"/>
        </visual>
    </link>

    <link name="toe_fl">
        <contact>
            <friction_anchor/>
            <stiffness value="30000.0"/>
            <damping value="1000.0"/>
            <spinning_friction value="0.3"/>
            <lateral_friction value="3.0"/>
        </contact>
<!--        <visual>-->
<!--            <origin rpy="0 0 0" xyz="0 0 0"/>-->
<!--            <geometry>-->
<!--                <sphere radius="0.0275"/>-->
<!--            </geometry>-->
<!--            <material name="darkgray"/>-->
<!--        </visual>-->
        <collision>
            <origin rpy="0 0 0" xyz="0 0 0"/>
            <geometry>
                <sphere radius="0.0275"/>
            </geometry>
        </collision>
        <inertial>
            <mass value="0.05"/>
            <!--            <mass value="0.005"/>-->
            <inertia ixx="0.000025" ixy="0" ixz="0" iyy="0.000025" iyz="0" izz="0.000025"/>
        </inertial>
    </link>

    <joint name="toe_fl_joint" type="fixed">
        <parent link="shank_fl"/>
        <child link="toe_fl"/>
        <origin xyz="0 0 -0.19"/>
        <dynamics damping="0.0" friction="0.0"/>
    </joint>

    <!--!!!!!!!!!!!!!!!!!!!! Hind Right Leg !!!!!!!!!!!!!!!!!!!!-->

    <joint name="torso_to_abduct_hr_j" type="continuous">
        <axis xyz="1 0 0"/>
        <origin rpy="0 0 0" xyz="-0.212 -0.051 0.0"/>
        <parent link="body"/>
        <child link="abduct_hr"/>
        <limit effort="18" lower="-6.28" upper="6.28" velocity="25"/>
        <dynamics damping="0.01" friction="0.2"/>
    </joint>

    <link name="abduct_hr">
        <inertial>
            <mass value="0.54"/>
            <origin xyz="-0.058 -0.00485 0."/>
            <inertia ixx="0.000391" ixy="0.000000" ixz="0.000000"
                     iyy="0.000739" iyz="0.000000" izz="0.000488"/>
        </inertial>
        <visual>
            <geometry>
                <!--mesh filename="meshes/bp_abad_rr.obj"/-->
                <mesh filename="meshes/bp_abad2.dae"/>
            </geometry>
            <origin rpy="0 0 3.1415926" xyz="0.063 0.0 0.0"/>
        </visual>
    </link>

    <joint name="abduct_hr_to_thigh_hr_j" type="continuous">
        <axis xyz="0 -1 0"/>
        <origin rpy="0.0 0.0 0.0" xyz="0.0 -0.085 0.00"/>
        <parent link="abduct_hr"/>
        <child link="thigh_hr"/>
        <limit effort="18" lower="-6.28" upper="6.28" velocity="25"/>
        <dynamics damping="0.01" friction="0.2"/>
    </joint>

    <link name="thigh_hr">
        <inertial>
            <mass value="0.636"/>
            <origin xyz="0.0 0.019 -0.01865"/>
            <inertia ixx="0.001724" ixy="0.0" ixz="0.0"
                     iyy="0.001907" iyz="0.000228" izz="0.000468"/>
        </inertial>
        <visual>
            <geometry>
                <!--mesh filename="meshes/bp_upper_fr.obj"/-->
                <mesh filename="meshes/bp_upper_r.dae"/>
            </geometry>
            <origin rpy="0.0 0.0 0.0" xyz="0.0 0.0 0.0"/>
        </visual>
    </link>

    <joint name="thigh_hr_to_knee_hr_j" type="continuous">
        <axis xyz="0 -1 0"/>
        <origin rpy="0.0 0 0.0" xyz="0.0 0.0 -0.201"/>
        <parent link="thigh_hr"/>
        <child link="shank_hr"/>
        <limit effort="27" lower="-6.28" upper="6.28" velocity="17"/>
        <dynamics damping="0.01" friction="0.2"/>
    </joint>

    <link name="shank_hr">
        <inertial>
            <mass value="0.064"/>
            <origin xyz="0.0 0.0 -0.0865"/>
            <inertia ixx="0.000716" ixy="0" ixz="0.0" iyy="0.000721" iyz="0" izz="0.000012"/>
        </inertial>
        <visual>
            <geometry>
                <!--                <mesh filename="meshes/bp_lower.obj"/>-->
                <mesh filename="meshes/bp_lower.dae"/>
            </geometry>
            <origin rpy="0.0 0 0.0" xyz="0.0 0.0 0.0"/>
        </visual>
    </link>

    <link name="toe_hr">
        <contact>
            <friction_anchor/>
            <stiffness value="30000.0"/>
            <damping value="1000.0"/>
            <spinning_friction value="0.3"/>
            <lateral_friction value="3.0"/>
        </contact>
<!--        <visual>-->
<!--            <origin rpy="0 0 0" xyz="0 0 0"/>-->
<!--            <geometry>-->
<!--                <sphere radius="0.0275"/>-->
<!--            </geometry>-->
<!--            <material name="darkgray"/>-->
<!--        </visual>-->
        <collision>
            <origin rpy="0 0 0" xyz="0 0 0"/>
            <geometry>
                <sphere radius="0.0275"/>
            </geometry>
        </collision>
        <inertial>
            <mass value="0.05"/>
            <!--            <mass value="0.005"/>-->
            <inertia ixx="0.000025" ixy="0" ixz="0" iyy="0.000025" iyz="0" izz="0.000025"/>
        </inertial>
    </link>

    <joint name="toe_hr_joint" type="fixed">
        <parent link="shank_hr"/>
        <child link="toe_hr"/>
        <origin xyz="0 0 -0.19"/>
        <dynamics damping="0.0" friction="0.0"/>
    </joint>

    <!--!!!!!!!!!!!!!!!!!!!! Hind Left Leg !!!!!!!!!!!!!!!!!!!!-->

    <joint name="torso_to_abduct_hl_j" type="continuous">
        <axis xyz="1 0 0"/>
        <origin rpy="0 0 0" xyz="-0.212 0.051 0.0"/>
        <parent link="body"/>
        <child link="abduct_hl"/>
        <limit effort="18" lower="-6.28" upper="6.28" velocity="25"/>
        <dynamics damping="0.01" friction="0.2"/>
    </joint>

    <link name="abduct_hl">
        <inertial>
            <mass value="0.54"/>
            <origin xyz="-0.058 0.00485 0."/>
            <inertia ixx="0.000391" ixy="0.000000" ixz="0.000000"
                     iyy="0.000739" iyz="0.000000" izz="0.000488"/>
        </inertial>
        <visual>
            <geometry>
                <!--mesh filename="meshes/bp_abad_rl.obj"/-->
                <mesh filename="meshes/bp_abad2.dae"/>
            </geometry>
            <origin rpy="3.1415926 0 3.1415926" xyz="0.063 0.0 0.0"/>
        </visual>
    </link>

    <joint name="abduct_hl_to_thigh_hl_j" type="continuous">
        <axis xyz="0 -1 0"/>
        <origin rpy="0.0 0.0 0.0" xyz="0.0 0.085 0.00"/>
        <parent link="abduct_hl"/>
        <child link="thigh_hl"/>
        <limit effort="18" lower="-6.28" upper="6.28" velocity="25"/>
        <dynamics damping="0.01" friction="0.2"/>
    </joint>

    <link name="thigh_hl">
        <inertial>
            <mass value="0.636"/>
            <origin xyz="0.0 -0.019 -0.01865"/>
            <inertia ixx="0.001724" ixy="0.0" ixz="0.0"
                     iyy="0.001907" iyz="-0.000228" izz="0.000468"/>
        </inertial>
        <visual>
            <geometry>
                <!--mesh filename="meshes/bp_upper_fl.obj"/-->
                <mesh filename="meshes/bp_upper_l.dae"/>
            </geometry>
            <origin rpy="0.0 0.0 0.0" xyz="0.0 0.0 0.0"/>
        </visual>
    </link>

    <joint name="thigh_hl_to_knee_hl_j" type="continuous">
        <axis xyz="0 -1 0"/>
        <origin rpy="0.0 0 0.0" xyz="0.0 0.0 -0.201"/>
        <parent link="thigh_hl"/>
        <child link="shank_hl"/>
        <limit effort="27" lower="-6.28" upper="6.28" velocity="17"/>
        <dynamics damping="0.01" friction="0.2"/>
    </joint>

    <link name="shank_hl">
        <inertial>
            <mass value="0.064"/>
            <origin xyz="0.0 0.0 -0.0865"/>
            <inertia ixx="0.000716" ixy="0" ixz="0.0" iyy="0.000721" iyz="0" izz="0.000012"/>
        </inertial>
        <visual>
            <geometry>
                <!--                <mesh filename="meshes/bp_lower.obj"/>-->
                <mesh filename="meshes/bp_lower.dae"/>
            </geometry>
            <origin rpy="0.0 0 0.0" xyz="0.0 0.0 0.0"/>
        </visual>
    </link>

    <link name="toe_hl">
        <contact>
            <friction_anchor/>
            <stiffness value="30000.0"/>
            <damping value="1000.0"/>
            <spinning_friction value="0.3"/>
            <lateral_friction value="3.0"/>
        </contact>
<!--        <visual>-->
<!--            <origin rpy="0 0 0" xyz="0 0 0"/>-->
<!--            <geometry>-->
<!--                <sphere radius="0.0275"/>-->
<!--            </geometry>-->
<!--            <material name="darkgray"/>-->
<!--        </visual>-->
        <collision>
            <origin rpy="0 0 0" xyz="0 0 0"/>
            <geometry>
                <sphere radius="0.0275"/>
            </geometry>
        </collision>
        <inertial>
            <mass value="0.05"/>
            <!--            <mass value="0.005"/>-->
            <inertia ixx="0.000025" ixy="0" ixz="0" iyy="0.000025" iyz="0" izz="0.000025"/>
        </inertial>
    </link>

    <joint name="toe_hl_joint" type="fixed">
        <parent link="shank_hl"/>
        <child link="toe_hl"/>
        <origin xyz="0 0 -0.19"/>
        <dynamics damping="0.0" friction="0.0"/>
    </joint>

</robot>
